2019-06-08 11:52:46,910 INFO     RDS:False
2019-06-08 11:52:46,934 INFO     database created
2019-06-08 11:52:50,622 INFO      * Running on http://127.0.0.1:5000/ (Press CTRL+C to quit)
2019-06-08 11:52:51,342 INFO     New prediction added.
2019-06-08 11:52:51,351 INFO     127.0.0.1 - - [08/Jun/2019 11:52:51] "POST /main HTTP/1.1" 200 -
2019-06-08 13:28:34,358 INFO     127.0.0.1 - - [08/Jun/2019 13:28:34] "GET / HTTP/1.1" 200 -
2019-06-08 13:28:44,125 INFO      * Running on http://127.0.0.1:5000/ (Press CTRL+C to quit)
2019-06-08 13:28:46,495 INFO     127.0.0.1 - - [08/Jun/2019 13:28:46] "GET /main HTTP/1.1" 200 -
2019-06-08 13:28:46,609 INFO     127.0.0.1 - - [08/Jun/2019 13:28:46] "GET /assets/startup.png HTTP/1.1" 404 -
2019-06-08 13:29:40,930 INFO      * Running on http://127.0.0.1:5000/ (Press CTRL+C to quit)
2019-06-08 13:29:43,884 INFO     127.0.0.1 - - [08/Jun/2019 13:29:43] "GET /main HTTP/1.1" 200 -
2019-06-08 13:29:44,006 INFO     127.0.0.1 - - [08/Jun/2019 13:29:44] "GET /assets/startup.png HTTP/1.1" 404 -
2019-06-08 13:31:40,165 INFO      * Running on http://127.0.0.1:5000/ (Press CTRL+C to quit)
2019-06-08 13:31:42,194 INFO     127.0.0.1 - - [08/Jun/2019 13:31:42] "GET /main HTTP/1.1" 200 -
2019-06-08 13:31:42,244 INFO     127.0.0.1 - - [08/Jun/2019 13:31:42] "GET /static/startup.png HTTP/1.1" 200 -
2019-06-08 13:33:19,207 INFO      * Running on http://127.0.0.1:5000/ (Press CTRL+C to quit)
2019-06-08 13:33:21,951 INFO     127.0.0.1 - - [08/Jun/2019 13:33:21] "GET /main HTTP/1.1" 200 -
2019-06-08 13:33:22,068 INFO     127.0.0.1 - - [08/Jun/2019 13:33:22] "GET /static/startup.png HTTP/1.1" 200 -
2019-06-08 13:34:07,373 INFO      * Running on http://127.0.0.1:5000/ (Press CTRL+C to quit)
2019-06-08 13:34:08,645 INFO     127.0.0.1 - - [08/Jun/2019 13:34:08] "GET /main HTTP/1.1" 200 -
2019-06-08 13:34:08,682 INFO     127.0.0.1 - - [08/Jun/2019 13:34:08] "GET /static/startup.png HTTP/1.1" 200 -
2019-06-08 13:34:31,659 INFO      * Running on http://127.0.0.1:5000/ (Press CTRL+C to quit)
2019-06-08 13:34:32,141 INFO     127.0.0.1 - - [08/Jun/2019 13:34:32] "GET /main HTTP/1.1" 200 -
2019-06-08 13:34:32,247 INFO     127.0.0.1 - - [08/Jun/2019 13:34:32] "GET /static/startup.png HTTP/1.1" 200 -
2019-06-08 13:34:56,347 INFO      * Running on http://127.0.0.1:5000/ (Press CTRL+C to quit)
2019-06-08 13:34:56,716 INFO     127.0.0.1 - - [08/Jun/2019 13:34:56] "GET /main HTTP/1.1" 200 -
2019-06-08 13:34:56,845 INFO     127.0.0.1 - - [08/Jun/2019 13:34:56] "GET /static/startup.png HTTP/1.1" 200 -
2019-06-08 13:37:27,562 INFO      * Running on http://127.0.0.1:5000/ (Press CTRL+C to quit)
2019-06-08 13:37:27,736 INFO     127.0.0.1 - - [08/Jun/2019 13:37:27] "GET /main HTTP/1.1" 200 -
2019-06-08 13:37:41,572 INFO      * Running on http://127.0.0.1:5000/ (Press CTRL+C to quit)
2019-06-08 13:37:41,885 INFO     127.0.0.1 - - [08/Jun/2019 13:37:41] "GET /main HTTP/1.1" 200 -
2019-06-08 13:47:18,549 INFO      * Running on http://127.0.0.1:5000/ (Press CTRL+C to quit)
2019-06-08 13:47:20,215 INFO     127.0.0.1 - - [08/Jun/2019 13:47:20] "GET / HTTP/1.1" 200 -
2019-06-08 13:47:20,263 INFO     127.0.0.1 - - [08/Jun/2019 13:47:20] "GET /static/startup_bg.jpg HTTP/1.1" 200 -
2019-06-08 13:57:20,158 INFO     127.0.0.1 - - [08/Jun/2019 13:57:20] "GET / HTTP/1.1" 200 -
2019-06-08 13:57:20,794 INFO     127.0.0.1 - - [08/Jun/2019 13:57:20] "GET / HTTP/1.1" 200 -
2019-06-08 13:57:29,506 INFO      * Running on http://127.0.0.1:5000/ (Press CTRL+C to quit)
2019-06-08 13:57:29,626 INFO     127.0.0.1 - - [08/Jun/2019 13:57:29] "GET / HTTP/1.1" 200 -
2019-06-08 13:58:14,167 INFO      * Running on http://127.0.0.1:5000/ (Press CTRL+C to quit)
2019-06-08 13:58:14,343 INFO     127.0.0.1 - - [08/Jun/2019 13:58:14] "GET / HTTP/1.1" 200 -
2019-06-08 13:58:29,036 INFO      * Running on http://127.0.0.1:5000/ (Press CTRL+C to quit)
2019-06-08 13:58:29,142 INFO     127.0.0.1 - - [08/Jun/2019 13:58:29] "GET / HTTP/1.1" 200 -
2019-06-08 13:59:59,099 INFO      * Running on http://127.0.0.1:5000/ (Press CTRL+C to quit)
2019-06-08 13:59:59,369 INFO     127.0.0.1 - - [08/Jun/2019 13:59:59] "GET / HTTP/1.1" 200 -
2019-06-08 14:00:00,172 INFO     127.0.0.1 - - [08/Jun/2019 14:00:00] "GET / HTTP/1.1" 200 -
2019-06-08 14:00:00,849 INFO     127.0.0.1 - - [08/Jun/2019 14:00:00] "GET / HTTP/1.1" 200 -
2019-06-08 14:00:22,218 INFO     127.0.0.1 - - [08/Jun/2019 14:00:22] "GET / HTTP/1.1" 200 -
2019-06-08 14:00:22,996 INFO     127.0.0.1 - - [08/Jun/2019 14:00:22] "GET / HTTP/1.1" 200 -
2019-06-08 14:04:47,999 INFO      * Running on http://127.0.0.1:5000/ (Press CTRL+C to quit)
2019-06-08 14:04:48,349 INFO     127.0.0.1 - - [08/Jun/2019 14:04:48] "GET / HTTP/1.1" 200 -
2019-06-08 14:06:49,933 INFO      * Running on http://127.0.0.1:5000/ (Press CTRL+C to quit)
2019-06-08 14:06:51,064 INFO     127.0.0.1 - - [08/Jun/2019 14:06:51] "GET / HTTP/1.1" 200 -
2019-06-08 14:11:45,412 INFO      * Running on http://127.0.0.1:5000/ (Press CTRL+C to quit)
2019-06-08 14:11:48,959 INFO     127.0.0.1 - - [08/Jun/2019 14:11:48] "GET / HTTP/1.1" 200 -
2019-06-08 14:11:50,035 INFO     127.0.0.1 - - [08/Jun/2019 14:11:50] "GET / HTTP/1.1" 200 -
2019-06-08 18:14:23,468 INFO     127.0.0.1 - - [08/Jun/2019 18:14:23] "GET /main HTTP/1.1" 200 -
2019-06-08 18:17:30,031 INFO     New prediction added.
2019-06-08 18:17:30,032 INFO     127.0.0.1 - - [08/Jun/2019 18:17:30] "POST /main HTTP/1.1" 200 -
2019-06-09 14:14:14,740 INFO     127.0.0.1 - - [09/Jun/2019 14:14:14] "GET /index HTTP/1.1" 404 -
2019-06-09 14:15:56,680 INFO      * Running on http://127.0.0.1:5000/ (Press CTRL+C to quit)
2019-06-09 14:15:57,738 ERROR    Exception on / [GET]
Traceback (most recent call last):
  File "/Applications/anaconda3/envs/startup_funding/lib/python3.7/site-packages/flask/app.py", line 2311, in wsgi_app
    response = self.full_dispatch_request()
  File "/Applications/anaconda3/envs/startup_funding/lib/python3.7/site-packages/flask/app.py", line 1834, in full_dispatch_request
    rv = self.handle_user_exception(e)
  File "/Applications/anaconda3/envs/startup_funding/lib/python3.7/site-packages/flask/app.py", line 1737, in handle_user_exception
    reraise(exc_type, exc_value, tb)
  File "/Applications/anaconda3/envs/startup_funding/lib/python3.7/site-packages/flask/_compat.py", line 36, in reraise
    raise value
  File "/Applications/anaconda3/envs/startup_funding/lib/python3.7/site-packages/flask/app.py", line 1832, in full_dispatch_request
    rv = self.dispatch_request()
  File "/Applications/anaconda3/envs/startup_funding/lib/python3.7/site-packages/flask/app.py", line 1818, in dispatch_request
    return self.view_functions[rule.endpoint](**req.view_args)
  File "/Users/finn/startup_funding/app/app.py", line 47, in index
    return(render_template('main.html'))
  File "/Applications/anaconda3/envs/startup_funding/lib/python3.7/site-packages/flask/templating.py", line 135, in render_template
    context, ctx.app)
  File "/Applications/anaconda3/envs/startup_funding/lib/python3.7/site-packages/flask/templating.py", line 117, in _render
    rv = template.render(context)
  File "/Applications/anaconda3/envs/startup_funding/lib/python3.7/site-packages/jinja2/asyncsupport.py", line 76, in render
    return original_render(self, *args, **kwargs)
  File "/Applications/anaconda3/envs/startup_funding/lib/python3.7/site-packages/jinja2/environment.py", line 1008, in render
    return self.environment.handle_exception(exc_info, True)
  File "/Applications/anaconda3/envs/startup_funding/lib/python3.7/site-packages/jinja2/environment.py", line 780, in handle_exception
    reraise(exc_type, exc_value, tb)
  File "/Applications/anaconda3/envs/startup_funding/lib/python3.7/site-packages/jinja2/_compat.py", line 37, in reraise
    raise value.with_traceback(tb)
  File "/Users/finn/startup_funding/app/templates/main.html", line 35, in top-level template code
    <form action="{{ url_for('main') }}" method="POST">
  File "/Applications/anaconda3/envs/startup_funding/lib/python3.7/site-packages/flask/helpers.py", line 356, in url_for
    return appctx.app.handle_url_build_error(error, endpoint, values)
  File "/Applications/anaconda3/envs/startup_funding/lib/python3.7/site-packages/flask/app.py", line 2080, in handle_url_build_error
    reraise(exc_type, exc_value, tb)
  File "/Applications/anaconda3/envs/startup_funding/lib/python3.7/site-packages/flask/_compat.py", line 36, in reraise
    raise value
  File "/Applications/anaconda3/envs/startup_funding/lib/python3.7/site-packages/flask/helpers.py", line 345, in url_for
    force_external=external)
  File "/Applications/anaconda3/envs/startup_funding/lib/python3.7/site-packages/werkzeug/routing.py", line 2007, in build
    raise BuildError(endpoint, values, method, self)
werkzeug.routing.BuildError: Could not build url for endpoint 'main'. Did you mean 'index' instead?
2019-06-09 14:15:57,755 INFO     127.0.0.1 - - [09/Jun/2019 14:15:57] "GET / HTTP/1.1" 500 -
2019-06-09 14:17:47,220 INFO      * Running on http://127.0.0.1:5000/ (Press CTRL+C to quit)
2019-06-09 14:17:50,976 ERROR    Exception on / [GET]
Traceback (most recent call last):
  File "/Applications/anaconda3/envs/startup_funding/lib/python3.7/site-packages/flask/app.py", line 2311, in wsgi_app
    response = self.full_dispatch_request()
  File "/Applications/anaconda3/envs/startup_funding/lib/python3.7/site-packages/flask/app.py", line 1834, in full_dispatch_request
    rv = self.handle_user_exception(e)
  File "/Applications/anaconda3/envs/startup_funding/lib/python3.7/site-packages/flask/app.py", line 1737, in handle_user_exception
    reraise(exc_type, exc_value, tb)
  File "/Applications/anaconda3/envs/startup_funding/lib/python3.7/site-packages/flask/_compat.py", line 36, in reraise
    raise value
  File "/Applications/anaconda3/envs/startup_funding/lib/python3.7/site-packages/flask/app.py", line 1832, in full_dispatch_request
    rv = self.dispatch_request()
  File "/Applications/anaconda3/envs/startup_funding/lib/python3.7/site-packages/flask/app.py", line 1818, in dispatch_request
    return self.view_functions[rule.endpoint](**req.view_args)
  File "/Users/finn/startup_funding/app/app.py", line 47, in index
    return(render_template('index.html'))
  File "/Applications/anaconda3/envs/startup_funding/lib/python3.7/site-packages/flask/templating.py", line 135, in render_template
    context, ctx.app)
  File "/Applications/anaconda3/envs/startup_funding/lib/python3.7/site-packages/flask/templating.py", line 117, in _render
    rv = template.render(context)
  File "/Applications/anaconda3/envs/startup_funding/lib/python3.7/site-packages/jinja2/asyncsupport.py", line 76, in render
    return original_render(self, *args, **kwargs)
  File "/Applications/anaconda3/envs/startup_funding/lib/python3.7/site-packages/jinja2/environment.py", line 1008, in render
    return self.environment.handle_exception(exc_info, True)
  File "/Applications/anaconda3/envs/startup_funding/lib/python3.7/site-packages/jinja2/environment.py", line 780, in handle_exception
    reraise(exc_type, exc_value, tb)
  File "/Applications/anaconda3/envs/startup_funding/lib/python3.7/site-packages/jinja2/_compat.py", line 37, in reraise
    raise value.with_traceback(tb)
  File "/Users/finn/startup_funding/app/templates/index.html", line 35, in top-level template code
    <form action="{{ url_for('main') }}" method="POST">
  File "/Applications/anaconda3/envs/startup_funding/lib/python3.7/site-packages/flask/helpers.py", line 356, in url_for
    return appctx.app.handle_url_build_error(error, endpoint, values)
  File "/Applications/anaconda3/envs/startup_funding/lib/python3.7/site-packages/flask/app.py", line 2080, in handle_url_build_error
    reraise(exc_type, exc_value, tb)
  File "/Applications/anaconda3/envs/startup_funding/lib/python3.7/site-packages/flask/_compat.py", line 36, in reraise
    raise value
  File "/Applications/anaconda3/envs/startup_funding/lib/python3.7/site-packages/flask/helpers.py", line 345, in url_for
    force_external=external)
  File "/Applications/anaconda3/envs/startup_funding/lib/python3.7/site-packages/werkzeug/routing.py", line 2007, in build
    raise BuildError(endpoint, values, method, self)
werkzeug.routing.BuildError: Could not build url for endpoint 'main'. Did you mean 'index' instead?
2019-06-09 14:17:50,989 INFO     127.0.0.1 - - [09/Jun/2019 14:17:50] "GET / HTTP/1.1" 500 -
2019-06-09 14:18:12,553 ERROR    Exception on / [GET]
Traceback (most recent call last):
  File "/Applications/anaconda3/envs/startup_funding/lib/python3.7/site-packages/flask/app.py", line 2311, in wsgi_app
    response = self.full_dispatch_request()
  File "/Applications/anaconda3/envs/startup_funding/lib/python3.7/site-packages/flask/app.py", line 1834, in full_dispatch_request
    rv = self.handle_user_exception(e)
  File "/Applications/anaconda3/envs/startup_funding/lib/python3.7/site-packages/flask/app.py", line 1737, in handle_user_exception
    reraise(exc_type, exc_value, tb)
  File "/Applications/anaconda3/envs/startup_funding/lib/python3.7/site-packages/flask/_compat.py", line 36, in reraise
    raise value
  File "/Applications/anaconda3/envs/startup_funding/lib/python3.7/site-packages/flask/app.py", line 1832, in full_dispatch_request
    rv = self.dispatch_request()
  File "/Applications/anaconda3/envs/startup_funding/lib/python3.7/site-packages/flask/app.py", line 1818, in dispatch_request
    return self.view_functions[rule.endpoint](**req.view_args)
  File "/Users/finn/startup_funding/app/app.py", line 47, in index
    return(render_template('index.html'))
  File "/Applications/anaconda3/envs/startup_funding/lib/python3.7/site-packages/flask/templating.py", line 135, in render_template
    context, ctx.app)
  File "/Applications/anaconda3/envs/startup_funding/lib/python3.7/site-packages/flask/templating.py", line 117, in _render
    rv = template.render(context)
  File "/Applications/anaconda3/envs/startup_funding/lib/python3.7/site-packages/jinja2/asyncsupport.py", line 76, in render
    return original_render(self, *args, **kwargs)
  File "/Applications/anaconda3/envs/startup_funding/lib/python3.7/site-packages/jinja2/environment.py", line 1008, in render
    return self.environment.handle_exception(exc_info, True)
  File "/Applications/anaconda3/envs/startup_funding/lib/python3.7/site-packages/jinja2/environment.py", line 780, in handle_exception
    reraise(exc_type, exc_value, tb)
  File "/Applications/anaconda3/envs/startup_funding/lib/python3.7/site-packages/jinja2/_compat.py", line 37, in reraise
    raise value.with_traceback(tb)
  File "/Users/finn/startup_funding/app/templates/index.html", line 35, in top-level template code
    <form action="{{ url_for('main') }}" method="POST">
  File "/Applications/anaconda3/envs/startup_funding/lib/python3.7/site-packages/flask/helpers.py", line 356, in url_for
    return appctx.app.handle_url_build_error(error, endpoint, values)
  File "/Applications/anaconda3/envs/startup_funding/lib/python3.7/site-packages/flask/app.py", line 2080, in handle_url_build_error
    reraise(exc_type, exc_value, tb)
  File "/Applications/anaconda3/envs/startup_funding/lib/python3.7/site-packages/flask/_compat.py", line 36, in reraise
    raise value
  File "/Applications/anaconda3/envs/startup_funding/lib/python3.7/site-packages/flask/helpers.py", line 345, in url_for
    force_external=external)
  File "/Applications/anaconda3/envs/startup_funding/lib/python3.7/site-packages/werkzeug/routing.py", line 2007, in build
    raise BuildError(endpoint, values, method, self)
werkzeug.routing.BuildError: Could not build url for endpoint 'main'. Did you mean 'index' instead?
2019-06-09 14:18:12,557 INFO     127.0.0.1 - - [09/Jun/2019 14:18:12] "GET / HTTP/1.1" 500 -
2019-06-09 14:18:15,003 ERROR    Exception on / [GET]
Traceback (most recent call last):
  File "/Applications/anaconda3/envs/startup_funding/lib/python3.7/site-packages/flask/app.py", line 2311, in wsgi_app
    response = self.full_dispatch_request()
  File "/Applications/anaconda3/envs/startup_funding/lib/python3.7/site-packages/flask/app.py", line 1834, in full_dispatch_request
    rv = self.handle_user_exception(e)
  File "/Applications/anaconda3/envs/startup_funding/lib/python3.7/site-packages/flask/app.py", line 1737, in handle_user_exception
    reraise(exc_type, exc_value, tb)
  File "/Applications/anaconda3/envs/startup_funding/lib/python3.7/site-packages/flask/_compat.py", line 36, in reraise
    raise value
  File "/Applications/anaconda3/envs/startup_funding/lib/python3.7/site-packages/flask/app.py", line 1832, in full_dispatch_request
    rv = self.dispatch_request()
  File "/Applications/anaconda3/envs/startup_funding/lib/python3.7/site-packages/flask/app.py", line 1818, in dispatch_request
    return self.view_functions[rule.endpoint](**req.view_args)
  File "/Users/finn/startup_funding/app/app.py", line 47, in index
    return(render_template('index.html'))
  File "/Applications/anaconda3/envs/startup_funding/lib/python3.7/site-packages/flask/templating.py", line 135, in render_template
    context, ctx.app)
  File "/Applications/anaconda3/envs/startup_funding/lib/python3.7/site-packages/flask/templating.py", line 117, in _render
    rv = template.render(context)
  File "/Applications/anaconda3/envs/startup_funding/lib/python3.7/site-packages/jinja2/asyncsupport.py", line 76, in render
    return original_render(self, *args, **kwargs)
  File "/Applications/anaconda3/envs/startup_funding/lib/python3.7/site-packages/jinja2/environment.py", line 1008, in render
    return self.environment.handle_exception(exc_info, True)
  File "/Applications/anaconda3/envs/startup_funding/lib/python3.7/site-packages/jinja2/environment.py", line 780, in handle_exception
    reraise(exc_type, exc_value, tb)
  File "/Applications/anaconda3/envs/startup_funding/lib/python3.7/site-packages/jinja2/_compat.py", line 37, in reraise
    raise value.with_traceback(tb)
  File "/Users/finn/startup_funding/app/templates/index.html", line 35, in top-level template code
    <form action="{{ url_for('main') }}" method="POST">
  File "/Applications/anaconda3/envs/startup_funding/lib/python3.7/site-packages/flask/helpers.py", line 356, in url_for
    return appctx.app.handle_url_build_error(error, endpoint, values)
  File "/Applications/anaconda3/envs/startup_funding/lib/python3.7/site-packages/flask/app.py", line 2080, in handle_url_build_error
    reraise(exc_type, exc_value, tb)
  File "/Applications/anaconda3/envs/startup_funding/lib/python3.7/site-packages/flask/_compat.py", line 36, in reraise
    raise value
  File "/Applications/anaconda3/envs/startup_funding/lib/python3.7/site-packages/flask/helpers.py", line 345, in url_for
    force_external=external)
  File "/Applications/anaconda3/envs/startup_funding/lib/python3.7/site-packages/werkzeug/routing.py", line 2007, in build
    raise BuildError(endpoint, values, method, self)
werkzeug.routing.BuildError: Could not build url for endpoint 'main'. Did you mean 'index' instead?
2019-06-09 14:18:15,004 INFO     127.0.0.1 - - [09/Jun/2019 14:18:15] "GET / HTTP/1.1" 500 -
2019-06-09 14:19:52,314 INFO      * Running on http://127.0.0.1:5000/ (Press CTRL+C to quit)
2019-06-09 14:20:01,651 INFO     127.0.0.1 - - [09/Jun/2019 14:20:01] "GET / HTTP/1.1" 200 -
2019-06-09 14:20:01,773 INFO     127.0.0.1 - - [09/Jun/2019 14:20:01] "GET /static/startup.png HTTP/1.1" 200 -
2019-06-09 14:20:36,985 INFO     New prediction added.
2019-06-09 14:20:36,986 INFO     127.0.0.1 - - [09/Jun/2019 14:20:36] "POST / HTTP/1.1" 200 -
2019-06-10 00:20:47,288 INFO      * Running on http://127.0.0.1:5000/ (Press CTRL+C to quit)
2019-06-10 00:20:55,205 INFO     127.0.0.1 - - [10/Jun/2019 00:20:55] "GET / HTTP/1.1" 200 -
2019-06-10 00:25:17,662 ERROR    Exception on / [POST]
Traceback (most recent call last):
  File "/Applications/anaconda3/envs/startup_funding/lib/python3.7/site-packages/sqlalchemy/engine/base.py", line 1244, in _execute_context
    cursor, statement, parameters, context
  File "/Applications/anaconda3/envs/startup_funding/lib/python3.7/site-packages/sqlalchemy/engine/default.py", line 552, in do_execute
    cursor.execute(statement, parameters)
sqlite3.OperationalError: no such table: funding_prediction

The above exception was the direct cause of the following exception:

Traceback (most recent call last):
  File "/Applications/anaconda3/envs/startup_funding/lib/python3.7/site-packages/flask/app.py", line 2311, in wsgi_app
    response = self.full_dispatch_request()
  File "/Applications/anaconda3/envs/startup_funding/lib/python3.7/site-packages/flask/app.py", line 1834, in full_dispatch_request
    rv = self.handle_user_exception(e)
  File "/Applications/anaconda3/envs/startup_funding/lib/python3.7/site-packages/flask/app.py", line 1737, in handle_user_exception
    reraise(exc_type, exc_value, tb)
  File "/Applications/anaconda3/envs/startup_funding/lib/python3.7/site-packages/flask/_compat.py", line 36, in reraise
    raise value
  File "/Applications/anaconda3/envs/startup_funding/lib/python3.7/site-packages/flask/app.py", line 1832, in full_dispatch_request
    rv = self.dispatch_request()
  File "/Applications/anaconda3/envs/startup_funding/lib/python3.7/site-packages/flask/app.py", line 1818, in dispatch_request
    return self.view_functions[rule.endpoint](**req.view_args)
  File "/Users/finn/startup_funding/app/app.py", line 107, in index
    db.session.commit()
  File "/Applications/anaconda3/envs/startup_funding/lib/python3.7/site-packages/sqlalchemy/orm/scoping.py", line 162, in do
    return getattr(self.registry(), name)(*args, **kwargs)
  File "/Applications/anaconda3/envs/startup_funding/lib/python3.7/site-packages/sqlalchemy/orm/session.py", line 1026, in commit
    self.transaction.commit()
  File "/Applications/anaconda3/envs/startup_funding/lib/python3.7/site-packages/sqlalchemy/orm/session.py", line 493, in commit
    self._prepare_impl()
  File "/Applications/anaconda3/envs/startup_funding/lib/python3.7/site-packages/sqlalchemy/orm/session.py", line 472, in _prepare_impl
    self.session.flush()
  File "/Applications/anaconda3/envs/startup_funding/lib/python3.7/site-packages/sqlalchemy/orm/session.py", line 2451, in flush
    self._flush(objects)
  File "/Applications/anaconda3/envs/startup_funding/lib/python3.7/site-packages/sqlalchemy/orm/session.py", line 2589, in _flush
    transaction.rollback(_capture_exception=True)
  File "/Applications/anaconda3/envs/startup_funding/lib/python3.7/site-packages/sqlalchemy/util/langhelpers.py", line 68, in __exit__
    compat.reraise(exc_type, exc_value, exc_tb)
  File "/Applications/anaconda3/envs/startup_funding/lib/python3.7/site-packages/sqlalchemy/util/compat.py", line 129, in reraise
    raise value
  File "/Applications/anaconda3/envs/startup_funding/lib/python3.7/site-packages/sqlalchemy/orm/session.py", line 2549, in _flush
    flush_context.execute()
  File "/Applications/anaconda3/envs/startup_funding/lib/python3.7/site-packages/sqlalchemy/orm/unitofwork.py", line 422, in execute
    rec.execute(self)
  File "/Applications/anaconda3/envs/startup_funding/lib/python3.7/site-packages/sqlalchemy/orm/unitofwork.py", line 589, in execute
    uow,
  File "/Applications/anaconda3/envs/startup_funding/lib/python3.7/site-packages/sqlalchemy/orm/persistence.py", line 245, in save_obj
    insert,
  File "/Applications/anaconda3/envs/startup_funding/lib/python3.7/site-packages/sqlalchemy/orm/persistence.py", line 1066, in _emit_insert_statements
    c = cached_connections[connection].execute(statement, multiparams)
  File "/Applications/anaconda3/envs/startup_funding/lib/python3.7/site-packages/sqlalchemy/engine/base.py", line 988, in execute
    return meth(self, multiparams, params)
  File "/Applications/anaconda3/envs/startup_funding/lib/python3.7/site-packages/sqlalchemy/sql/elements.py", line 287, in _execute_on_connection
    return connection._execute_clauseelement(self, multiparams, params)
  File "/Applications/anaconda3/envs/startup_funding/lib/python3.7/site-packages/sqlalchemy/engine/base.py", line 1107, in _execute_clauseelement
    distilled_params,
  File "/Applications/anaconda3/envs/startup_funding/lib/python3.7/site-packages/sqlalchemy/engine/base.py", line 1248, in _execute_context
    e, statement, parameters, cursor, context
  File "/Applications/anaconda3/envs/startup_funding/lib/python3.7/site-packages/sqlalchemy/engine/base.py", line 1466, in _handle_dbapi_exception
    util.raise_from_cause(sqlalchemy_exception, exc_info)
  File "/Applications/anaconda3/envs/startup_funding/lib/python3.7/site-packages/sqlalchemy/util/compat.py", line 383, in raise_from_cause
    reraise(type(exception), exception, tb=exc_tb, cause=cause)
  File "/Applications/anaconda3/envs/startup_funding/lib/python3.7/site-packages/sqlalchemy/util/compat.py", line 128, in reraise
    raise value.with_traceback(tb)
  File "/Applications/anaconda3/envs/startup_funding/lib/python3.7/site-packages/sqlalchemy/engine/base.py", line 1244, in _execute_context
    cursor, statement, parameters, context
  File "/Applications/anaconda3/envs/startup_funding/lib/python3.7/site-packages/sqlalchemy/engine/default.py", line 552, in do_execute
    cursor.execute(statement, parameters)
sqlalchemy.exc.OperationalError: (sqlite3.OperationalError) no such table: funding_prediction
[SQL: INSERT INTO funding_prediction (startup_name, num_rounds, time_first_round, time_btw_round, funding_type, founding_date, country, investor_type, acq_type, market, prediction) VALUES (?, ?, ?, ?, ?, ?, ?, ?, ?, ?, ?)]
[parameters: ('night_test', 5, 2, 1, 'funding_round_type_post_ipo_equity', '2012-12', 'country_chn', 2, 0, 'market_mobile', '2,685')]
(Background on this error at: http://sqlalche.me/e/e3q8)
2019-06-10 00:25:17,686 INFO     127.0.0.1 - - [10/Jun/2019 00:25:17] "POST / HTTP/1.1" 500 -
2019-06-10 00:26:38,107 INFO     RDS:False
2019-06-10 00:26:38,133 INFO     database created
2019-06-10 00:26:43,494 INFO      * Running on http://127.0.0.1:5000/ (Press CTRL+C to quit)
2019-06-10 00:26:45,540 INFO     New prediction added.
2019-06-10 00:26:45,549 INFO     127.0.0.1 - - [10/Jun/2019 00:26:45] "POST / HTTP/1.1" 200 -
